Traceback (most recent call last):
  File "C:\Users\cxcs\Anaconda3\lib\site-packages\jupyter_cache\executors\utils.py", line 51, in single_nb_execution
    executenb(
  File "C:\Users\cxcs\Anaconda3\lib\site-packages\nbclient\client.py", line 1112, in execute
    return NotebookClient(nb=nb, resources=resources, km=km, **kwargs).execute()
  File "C:\Users\cxcs\Anaconda3\lib\site-packages\nbclient\util.py", line 74, in wrapped
    return just_run(coro(*args, **kwargs))
  File "C:\Users\cxcs\Anaconda3\lib\site-packages\nbclient\util.py", line 53, in just_run
    return loop.run_until_complete(coro)
  File "C:\Users\cxcs\Anaconda3\lib\asyncio\base_events.py", line 642, in run_until_complete
    return future.result()
  File "C:\Users\cxcs\Anaconda3\lib\site-packages\nbclient\client.py", line 553, in async_execute
    await self.async_execute_cell(
  File "C:\Users\cxcs\Anaconda3\lib\site-packages\nbclient\client.py", line 857, in async_execute_cell
    self._check_raise_for_error(cell, exec_reply)
  File "C:\Users\cxcs\Anaconda3\lib\site-packages\nbclient\client.py", line 760, in _check_raise_for_error
    raise CellExecutionError.from_cell_and_msg(cell, exec_reply_content)
nbclient.exceptions.CellExecutionError: An error occurred while executing the following cell:
------------------
import cdsapi
c = cdsapi.Client()
c.retrieve(
    'reanalysis-era5-land',
    {
        'variable': [
            '10m_u_component_of_wind', '10m_v_component_of_wind', '2m_temperature',
        ],
        'year': [
            '1981', '1982', '1983',
            '1984', '1985', '1986',
            '1987', '1988', '1989',
            '1990', '1991', '1992',
            '1993', '1994', '1995',
            '1996', '1997', '1998',
            '1999', '2000', '2001',
            '2002', '2003', '2004',
            '2005', '2006', '2007',
            '2008', '2009', '2010',
            '2011', '2012', '2013',
            '2014', '2015', '2016',
            '2017', '2018', '2019',
            '2020',
        ],
        'month': '12',
        'day': '15',
        'time': '12:00',
        'format': 'netcdf',
        'area': [
            60, -10, 35,
            30,
        ],
    },
    './data/era5-land_eur_1981_2020.nc')
------------------

[1;31m---------------------------------------------------------------------------[0m
[1;31mFileNotFoundError[0m                         Traceback (most recent call last)
[1;32m~\AppData\Local\Temp/ipykernel_9084/1706028111.py[0m in [0;36m<module>[1;34m[0m
[0;32m      1[0m [1;32mimport[0m [0mcdsapi[0m[1;33m[0m[1;33m[0m[0m
[0;32m      2[0m [0mc[0m [1;33m=[0m [0mcdsapi[0m[1;33m.[0m[0mClient[0m[1;33m([0m[1;33m)[0m[1;33m[0m[1;33m[0m[0m
[1;32m----> 3[1;33m c.retrieve(
[0m[0;32m      4[0m     [1;34m'reanalysis-era5-land'[0m[1;33m,[0m[1;33m[0m[1;33m[0m[0m
[0;32m      5[0m     {

[1;32m~\Anaconda3\lib\site-packages\cdsapi\api.py[0m in [0;36mretrieve[1;34m(self, name, request, target)[0m
[0;32m    348[0m         [0mresult[0m [1;33m=[0m [0mself[0m[1;33m.[0m[0m_api[0m[1;33m([0m[1;34m"%s/resources/%s"[0m [1;33m%[0m [1;33m([0m[0mself[0m[1;33m.[0m[0murl[0m[1;33m,[0m [0mname[0m[1;33m)[0m[1;33m,[0m [0mrequest[0m[1;33m,[0m [1;34m"POST"[0m[1;33m)[0m[1;33m[0m[1;33m[0m[0m
[0;32m    349[0m         [1;32mif[0m [0mtarget[0m [1;32mis[0m [1;32mnot[0m [1;32mNone[0m[1;33m:[0m[1;33m[0m[1;33m[0m[0m
[1;32m--> 350[1;33m             [0mresult[0m[1;33m.[0m[0mdownload[0m[1;33m([0m[0mtarget[0m[1;33m)[0m[1;33m[0m[1;33m[0m[0m
[0m[0;32m    351[0m         [1;32mreturn[0m [0mresult[0m[1;33m[0m[1;33m[0m[0m
[0;32m    352[0m [1;33m[0m[0m

[1;32m~\Anaconda3\lib\site-packages\cdsapi\api.py[0m in [0;36mdownload[1;34m(self, target)[0m
[0;32m    171[0m [1;33m[0m[0m
[0;32m    172[0m     [1;32mdef[0m [0mdownload[0m[1;33m([0m[0mself[0m[1;33m,[0m [0mtarget[0m[1;33m=[0m[1;32mNone[0m[1;33m)[0m[1;33m:[0m[1;33m[0m[1;33m[0m[0m
[1;32m--> 173[1;33m         [1;32mreturn[0m [0mself[0m[1;33m.[0m[0m_download[0m[1;33m([0m[0mself[0m[1;33m.[0m[0mlocation[0m[1;33m,[0m [0mself[0m[1;33m.[0m[0mcontent_length[0m[1;33m,[0m [0mtarget[0m[1;33m)[0m[1;33m[0m[1;33m[0m[0m
[0m[0;32m    174[0m [1;33m[0m[0m
[0;32m    175[0m     [1;33m@[0m[0mproperty[0m[1;33m[0m[1;33m[0m[0m

[1;32m~\Anaconda3\lib\site-packages\cdsapi\api.py[0m in [0;36m_download[1;34m(self, url, size, target)[0m
[0;32m    130[0m                 ) as pbar:
[0;32m    131[0m                     [0mpbar[0m[1;33m.[0m[0mupdate[0m[1;33m([0m[0mtotal[0m[1;33m)[0m[1;33m[0m[1;33m[0m[0m
[1;32m--> 132[1;33m                     [1;32mwith[0m [0mopen[0m[1;33m([0m[0mtarget[0m[1;33m,[0m [0mmode[0m[1;33m)[0m [1;32mas[0m [0mf[0m[1;33m:[0m[1;33m[0m[1;33m[0m[0m
[0m[0;32m    133[0m                         [1;32mfor[0m [0mchunk[0m [1;32min[0m [0mr[0m[1;33m.[0m[0miter_content[0m[1;33m([0m[0mchunk_size[0m[1;33m=[0m[1;36m1024[0m[1;33m)[0m[1;33m:[0m[1;33m[0m[1;33m[0m[0m
[0;32m    134[0m                             [1;32mif[0m [0mchunk[0m[1;33m:[0m[1;33m[0m[1;33m[0m[0m

[1;31mFileNotFoundError[0m: [Errno 2] No such file or directory: './data/era5-land_eur_1981_2020.nc'
FileNotFoundError: [Errno 2] No such file or directory: './data/era5-land_eur_1981_2020.nc'

